Workbook
Name ㅇㅇㅂㅈㄷㅇㅂㅈ: #REF!
Name ㅇㅇㅇㄷ: #REF!
Name OS_목록: #REF!
Name ㅇ: #REF!
Name 기준반영: #REF!
Name test: #REF!
Name ㅇㅇㅇ: #REF!
Name 기준반영: #REF!
Name ㅇ: #REF!
Name 빠씨: #REF!
Name test: #REF!
Name a: #REF!
Name s: #REF!
Name 버전: #REF!
Name 문서화요구사항: #REF!
Name s: #REF!
Name 동의여부: #REF!
Name 적정성: #REF!
Name 동의여부: #REF!
Name 적정성: #REF!
Name ㅇㄹㅇ: #REF!

Sheet 표지
B10: 자산관리대장
B22: 45951
M26: 문서버전 | N26: v 1.1
M27: 수행사 | N27: ㅇㅇㅇ
M28: 작성자 | N28: 이윤혁

Sheet 제∙개정 이력
B2: 제∙개정 이력
B4: 차수 | C4: Version | D4: 개정내용 | E4: 개정일자 | F4: 작성자
B5: 1 | C5: 1 | D5: 신규 작성 | E5: 45801 | F5: 주상욱
B6: 2 | C6: 1.1 | D6: 자산 업데이트 | E6: 45951 | F6: 이예은

Sheet 자산분류기준
B2: 자산 분석 및 중요도 평가
C4: 가. 목적 자산 분석 및 중요도 평가는 자산의 가치 및 중요도에 따른 보호수준을 분류하여 자산을 효율적으로 관리하도록 하는 데에 목적이 있다.
C5: 나. 분류 기준 자산을 유형, 속성 및 관리의 편의성 등을 고려하여 10가지 유형으로 분류하였다.
B7: No | C7: 분류 | D7: 설명 | E7: 비고
B8: 1 | C8: 서버 | D8: 네트워크를 통해 정보나 서비스를 제공하는 컴퓨팅 시스템, OS기반의 가상 서버 서비스, 컨테이너 기반 서비스, Application 소스 배포 기반 서비스 등 | E8: - Windows / Linux / Unix Server 등 - EC2, ECS, Beanstalk 등
B9: 2 | C9: 네트워크 | D9: 서비스 운영 및 제반 업무를 위해 설치된 네트워크 장비 | E9: - 공유기, 라우터, 허브, 스위치(L4/L3/L2) 등 - VPC, ELB, NLB, ALB 등
B10: 3 | C10: DBMS | D10: 사용자가 데이터에 접근하여 데이터를 저장 및 관리 등의 기능을 제공하는 응용 소프트웨어 | E10: MySQL, Oracle, MSSQL, MariaDB, RDS, Redshift 등
B11: 4 | C11: 스토리지 | D11: MA, MBP 서비스를 제공하기 위한 목적으로 사용되는 스토리지 모인 중요 정보를 보관하고 있는 스토리지 | E11: S3 등
B12: 5 | C12: 정보보호시스템 | D12: 서비스 보안 운영을 위한 장비 | E12: 방화벽, VPN, IPS, 백신 등
B13: 6 | C13: 지원서비스 | D13: 서버, DB, 스토리지 등의 정보자산이 안정적·안전하게 운영될 수 있도록 지원하는 관리형 서비스 | E13: KMS, Secrets Manager, Lambda, API Gateway, CloudWatch 등
B14: 7 | C14: URL | D14: 회사, 제품, 판매 등 정보 및 서비스를 제공하기 위하여 인터넷상 구축·운영되는 서비스 | E14: - MA, MBP 웹 서비스 - MA IOS, AOS - API URL
B15: 8 | C15: PC (업무망,운영망) | D15: 모인 서비스 업무 및 운영에 접속하기 위한 단말기 | E15: 데스크탑, 노트북 등
B16: 9 | C16: 문서 | D16: 회사에서 관리되는 문서 | E16: - 정보보호 규정 및 지침
B17: 10 | C17: 소프트웨어 | D17: OS, 오피스 및 상용 소프트웨어
B19: 자산유형 | D19: 설명 | E19: 예시
B20: 온 프 레 미 스 | C20: 서버 | D20: 네트워크를 통해 정보나 서비스를 제공하는 컴퓨팅 시스템 | E20: Unix, Linux, Windows 등
C21: 네트워크 | D21: 네트워크 단위 들을 연결하는 통신 장비 | E21: 라우터, 스위치 등
C22: DBMS | D22: 데이터베이스 내의 데이터를 접근할 수 있도록 해주는 소프트웨어 도구 | E22: Oracle, MySQL, MSSQL 등
C23: 보안시스템 | D23: 정보자산의 보호를 위한 시스템 | E23: 방화벽, IPS, VPN, 백신 등
B24: 퍼 블 릭 클 라 우 드 | C24: 서버 | D24: OS 기반의 가상서버 서비스 | E24: EC2
D25: 컨테이너 기반 서비스 | E25: ECS
D26: Application 소스배포 기반 서비스 | E26: Beanstalk
D27: 가용성에 따라 증감되는 컴퓨팅 서비스 | E27: Auto Scaling
C28: 스토리지 | D28: 정보가 저장되는 객체 서비스 | E28: S3(Simple Storage Service)
C29: 네트워크 | D29: 사설 NW 영역에 EC2를 배치할 수 있는 논리적 네트워크 | E29: VPC(Virtual Private Cloud)
D30: 네트워크 로드밸런서 | E30: ELB, NLB, ALB 등
C31: DBMS | D31: 관계형 데이터베이스 | E31: RDS(Amazon, Aurora, MySQL 등)
D32: 관리형 데이터웨어하우스 | E32: Redshift
C33: 보안시스템 | D33: 정보자산의 보호를 위한 시스템 | E33: VPN, WAF 등
B34: URL | D34: 홈페이지 URL
B35: 문서 | D35: 회사에서 관리되는 출력물
B36: PC | D36: 업무용 단말기 | E36: PC, 노트북 등
B37: 소프트웨어 | D37: OS, 오피스 및 상용 소프트웨어
B38: 시설 | D38: 물리적 보호를 위한 시스템 | E38: 출입통제, CCTV, 소방설비 등
B39: 인력 | D39: 정보자산에 접근하거나 중요⋅개인정보를 처리하는 임직원

Sheet 1. 서버
B2: 서버 목록
B4: 자산분류 | D4: ='자산분류기준'!C8 -> 서버
B5: 설명 | D5: ='자산분류기준'!D8 -> 네트워크를 통해 정보나 서비스를 제공하는 컴퓨팅 시스템, OS기반의 가상 서버 서비스, 컨테이너 기반 서비스, Application 소스 배포 기반 서비스 등
C7: 자산정보 | O7: 관리자 정보 | R7: 자산중요도 평가항목 | W7: 비고
B8: No | C8: 위치 | D8: 유형 | E8: 구분 | F8: 서비스 구분 | G8: 서버 ID | H8: 호스트네임 | I8: OS Ver. | J8: OS 이미지 | K8: Public IP | L8: Private IP | M8: 사용유무 | N8: 용도 | O8: 관리부서 | P8: 책임자 | Q8: 운영자 | R8: 기밀성(C) | S8: 무결성(I) | T8: 가용성(A) | U8: 합계 | V8: 자산등급
B9: 1 | C9: 평촌 IDC | D9: 서버 | E9: 대외계 프록시 | F9: 공통 | G9: - | H9: KR-IDC-PROXY-2 | I9: RHEL | J9: - | K9: - | L9: 10.13.0.5 | M9: O | N9: 대외계 전문 교환 | O9: DEVOPS | P9: 백지훈 | Q9: 서동진 | U9: =SUM(R9:T9) -> 0 | V9: =IF(U9>7,"1등급",(IF(U9>4,"2등급",(IF(U9>2,"3등급","")))))
B10: 2 | C10: 평촌 IDC | D10: 서버 | E10: 대외계 프록시 | F10: 공통 | G10: - | H10: KR-IDC-PROXY-1 | I10: RHEL | J10: - | K10: - | L10: 10.13.0.3 | M10: O | N10: 대외계 프록시 | O10: DEVOPS | P10: 백지훈 | Q10: 서동진 | U10: =SUM(R10:T10) -> 0 | V10: =IF(U10>7,"1등급",(IF(U10>4,"2등급",(IF(U10>2,"3등급","")))))
B11: 3 | C11: moinaws(016954873025) | D11: ECS Node | E11: EC2(ECS Node) | F11: 공통 | G11: i-01b9ea35bd46e303c | H11: core-ecs-node | I11: AmazonLinux2 | J11: ami-02ab3ad3a4cc33164 | K11: - | L11: 10.30.3.74 | M11: O | N11: PRD / ECS Node / Core | O11: DEVOPS | P11: 백지훈 | Q11: 서동진
B12: 4 | C12: moinaws(016954873025) | D12: 서버 | E12: EC2 | F12: 공통 | G12: i-0e55bfd3d115c1664 | H12: moin-prd-core-v1-31-worker | I12: bottlerocket | J12: ami-059f9c1a10323833a | K12: - | L12: 10.30.174.149 | M12: O | N12: PRD K8S Worker Node | O12: DEVOPS | P12: 백지훈 | Q12: 서동진
B13: 5 | C13: moinaws(016954873025) | D13: 서버 | E13: H-IPS(EC2) | F13: 공통 | G13: i-06f8c3d48c471d443 | H13: moin-prd-ips | I13: Red Hat Enterprise Linux release 8.6 (Ootpa) | J13: ami-06c568b08b5a431d5 | K13: - | L13: 10.14.3.40 | M13: O | N13: IPS | O13: 정보보안팀 | P13: 이윤혁 | Q13: 주상욱 | W13: 마이그레이션 진행 중(삭제 예정)
B14: 6 | C14: moinaws(016954873025) | D14: ECS Node | E14: EC2(ECS Node) | F14: 공통 | G14: i-05b1e3cf477e790b6 | H14: core-ecs-node | I14: AmazonLinux2 | J14: ami-02ab3ad3a4cc33164 | K14: - | L14: 10.30.2.36 | M14: O | N14: PRD / ECS Node / Core | O14: DEVOPS | P14: 백지훈 | Q14: 서동진
B15: 7 | C15: moinaws(016954873025) | D15: 서버 | E15: EC2 | F15: 공통 | G15: i-01a310dd87ba3d927 | H15: moin-prd-core-v1-31-worker | I15: bottlerocket | J15: ami-0289946f24d54f017 | K15: - | L15: 10.30.132.170 | M15: O | N15: PRD K8S Worker Node | O15: DEVOPS | P15: 백지훈 | Q15: 서동진
B16: 8 | C16: moinaws(016954873025) | D16: 서버 | E16: EC2 | F16: 공통 | G16: i-064ad63110cf8c1d4 | H16: karpenter | I16: bottlerocket | J16: ami-0c71f8d590c5ade3f | K16: - | L16: 10.30.157.93 | M16: O | N16: PRD / K8S / Node ctrl | O16: DEVOPS | P16: 백지훈 | Q16: 서동진
B17: 9 | C17: moinaws(016954873025) | D17: 서버 | E17: EC2 | F17: 공통 | G17: i-0340d73edd9ccb075 | H17: moin-prd-core-v1-31-worker | I17: bottlerocket | J17: ami-0c71f8d590c5ade3f | K17: - | L17: 10.30.152.127 | M17: O | N17: PRD K8S Worker Node | O17: DEVOPS | P17: 백지훈 | Q17: 서동진
B18: 10 | C18: moinaws(016954873025) | D18: 서버 | E18: EC2 | F18: 공통 | G18: i-016fbe087fe9bab2a | H18: moin-prd-core-v1-31-worker | I18: bottlerocket | J18: ami-0289946f24d54f017 | K18: - | L18: 10.30.157.123 | M18: O | N18: PRD K8S Worker Node | O18: DEVOPS | P18: 백지훈 | Q18: 서동진
B19: 11 | C19: moinaws(016954873025) | D19: ECS Node | E19: EC2(ECS Node) | F19: MBP | G19: i-009b5960091997fb0 | H19: mbp-ecs-node | I19: AmazonLinux2 | J19: ami-0c57b1d5df97f7714 | K19: - | L19: 10.25.3.31 | M19: O | N19: PRD / ECS Node / MBP | O19: DEVOPS | P19: 백지훈 | Q19: 서동진
B20: 12 | C20: moinaws(016954873025) | D20: 서버 | E20: EC2 | F20: 공통 | G20: i-010766b8052f678fc | H20: moin-prd-core-v1-31-worker | I20: bottlerocket | J20: ami-0289946f24d54f017 | K20: - | L20: 10.30.68.140 | M20: O | N20: PRD K8S Worker Node | O20: DEVOPS | P20: 백지훈 | Q20: 서동진
B21: 13 | C21: moinaws(016954873025) | D21: ECS Node | E21: EC2(ECS Node) | F21: MBP | G21: i-07e5a3d2fbfe8ddef | H21: mbp-ecs-node | I21: AmazonLinux2 | J21: ami-0c57b1d5df97f7714 | K21: - | L21: 10.25.2.245 | M21: O | N21: PRD / ECS Node / MBP | O21: DEVOPS | P21: 백지훈 | Q21: 서동진
B22: 14 | C22: moinaws(016954873025) | D22: 서버 | E22: EC2 | F22: 공통 | G22: i-0fe5d2991625918cf | H22: moin-prd-core-v1-31-worker | I22: bottlerocket | J22: ami-0289946f24d54f017 | K22: - | L22: 10.30.106.17 | M22: O | N22: PRD K8S Worker Node | O22: DEVOPS | P22: 백지훈 | Q22: 서동진
B23: 15 | C23: moinaws(016954873025) | D23: ECS Node | E23: EC2(ECS Node) | F23: MBP | G23: i-020facda65f40a1be | H23: mbp-ecs-node | I23: AmazonLinux2 | J23: ami-0c57b1d5df97f7714 | K23: - | L23: 10.25.3.69 | M23: O | N23: PRD / ECS Node / MBP | O23: DEVOPS | P23: 백지훈 | Q23: 서동진
B24: 16 | C24: moinaws(016954873025) | D24: ECS Node | E24: EC2(ECS Node) | F24: 공통 | G24: i-0a7fb2a616215a370 | H24: core-ecs-node | I24: AmazonLinux2 | J24: ami-09d531103504c1daa | K24: - | L24: 10.30.3.201 | M24: O | N24: PRD / ECS Node / Core | O24: DEVOPS | P24: 백지훈 | Q24: 서동진
B25: 17 | C25: moinaws(016954873025) | D25: 서버 | E25: EC2 | F25: 공통 | G25: i-0f3b27b9aa319b3ef | H25: moin-prd-core-v1-31-worker | I25: bottlerocket | J25: ami-059f9c1a10323833a | K25: - | L25: 10.30.155.50 | M25: O | N25: PRD K8S Worker Node | O25: DEVOPS | P25: 백지훈 | Q25: 서동진
... B49: 41 | C49: moinaws(016954873025) | D49: ECS Cluster | E49: ECS Cluster | F49: (TERMINATED) | G49: - | H49: default | I49: - | J49: - | K49: - | L49: - | M49: X | N49: N/A | O49: DEVOPS | P49: 백지훈 | Q49: 서동진
B50: 42 | C50: moinaws_dev(458493682543) | D50: 서버 | E50: EC2 | F50: 공통 | G50: i-006b20de69ed123ee | H50: moin-dev-core-v1-31-worker | I50: bottlerocket | J50: ami-0289946f24d54f017 | L50: 10.204.69.247 | M50: O | N50: DEV K8S Worker Node | O50: DEVOPS | P50: 백지훈 | Q50: 서동진
B51: 43 | C51: moinaws_dev(458493682543) | D51: 서버 | E51: EC2 | F51: CORE | G51: i-0ef83f0751c0051b4 | H51: console-core-wkb-proxy-x86 | I51: AmazonLinux2023 | J51: ami-0482792c89ace383e | K51: 15.165.146.111 | L51: 10.204.0.142 | M51: running | N51: DEV 전문교환 테스트 서버 | O51: DEVOPS | P51: 백지훈 | Q51: 서동진
B52: 44 | C52: moinaws_dev(458493682543) | D52: ECS Node | E52: EC2(ECS Node) | F52: MBP | G52: i-03ad725f5ca14ad9b | H52: mbp-ecs-node | I52: AmazonLinux2 | J52: ami-0dfe80c71e294b99a | K52: - | L52: 10.203.2.199 | M52: running | N52: DEV / ECS Node / MBP | O52: DEVOPS | P52: 백지훈 | Q52: 서동진
B53: 45 | C53: moinaws_dev(458493682543) | D53: 서버 | E53: EC2 | F53: 공통 | G53: i-064ef7203c6874fb5 | H53: moin-dev-core-v1-31-worker | I53: bottlerocket | J53: ami-0289946f24d54f017 | K53: - | L53: 10.204.88.255 | M53: O | N53: DEV K8S Worker Node | O53: DEVOPS | P53: 백지훈 | Q53: 서동진
B54: 46 | C54: moinaws_dev(458493682543) | D54: 서버 | E54: EC2 | F54: 공통 | G54: i-030670f2ca5dac4d7 | H54: moin-dev-core-v1-31-worker | I54: bottlerocket | J54: ami-0289946f24d54f017 | K54: - | L54: 10.204.188.220 | M54: O | N54: DEV K8S Worker Node | O54: DEVOPS | P54: 백지훈 | Q54: 서동진
B55: 47 | C55: moinaws_dev(458493682543) | D55: 서버 | E55: EC2 | F55: 공통 | G55: i-01c3f5b2bfb7091b6 | H55: moin-dev-core-v1-31-worker | I55: bottlerocket | J55: ami-0289946f24d54f017 | K55: - | L55: 10.204.75.10 | M55: O | N55: DEV K8S Worker Node | O55: DEVOPS | P55: 백지훈 | Q55: 서동진
B56: 48 | C56: moinaws_dev(458493682543) | D56: 서버 | E56: EC2 | F56: 공통 | G56: i-054e97f1b8d39bec6 | H56: moin-dev-core-v1-31-worker | I56: bottlerocket | J56: ami-0289946f24d54f017 | K56: - | L56: 10.204.152.39 | M56: O | N56: DEV K8S Worker Node | O56: DEVOPS | P56: 백지훈 | Q56: 서동진
B57: 49 | C57: moinaws_dev(458493682543) | D57: 서버 | E57: EC2 | F57: 공통 | G57: i-0fd43f823860da198 | H57: moin-dev-core-v1-31-worker | I57: bottlerocket | J57: ami-0289946f24d54f017 | K57: - | L57: 10.204.85.241 | M57: O | N57: DEV K8S Worker Node | O57: DEVOPS | P57: 백지훈 | Q57: 서동진
B58: 50 | C58: moinaws_dev(458493682543) | D58: 서버 | E58: EC2 | F58: 공통 | G58: i-0b5c1a71e9b8732de | H58: moin-dev-core-v1-31-worker | I58: bottlerocket | J58: ami-0289946f24d54f017 | K58: - | L58: 10.204.107.167 | M58: O | N58: DEV K8S Worker Node | O58: DEVOPS | P58: 백지훈 | Q58: 서동진
B59: 51 | C59: moinaws_dev(458493682543) | D59: 서버 | E59: EC2 | F59: (TERMINATED) | G59: i-037717c480244b17d | H59: console-core-wazuh-poc | I59: AmazonLinux2 | J59: ami-0edde3c148312cc1e | K59: 43.202.229.102 | L59: 10.204.0.194 | M59: X | N59: N/A | O59: DEVOPS | P59: 백지훈 | Q59: 서동진
B60: 52 | C60: moinaws_dev(458493682543) | D60: ECS Node | E60: EC2(ECS Node) | F60: MBP | G60: i-08703ae828fdbd457 | H60: mbp-ecs-node | I60: AmazonLinux2 | J60: ami-0dfe80c71e294b99a | K60: - | L60: 10.203.2.70 | M60: running | N60: DEV / ECS Node / MBP | O60: DEVOPS | P60: 백지훈 | Q60: 서동진
B61: 53 | C61: moinaws_dev(458493682543) | D61: 서버 | E61: EC2 | F61: 공통 | G61: i-081f32d5acf8fe29d | H61: moin-dev-core-v1-31-worker | I61: bottlerocket | J61: ami-0289946f24d54f017 | K61: - | L61: 10.204.134.178 | M61: O | N61: DEV K8S Worker Node | O61: DEVOPS | P61: 백지훈 | Q61: 서동진
B62: 54 | C62: moinaws_dev(458493682543) | D62: ECS Node | E62: EC2(ECS Node) | F62: MBP | G62: i-0eb12eda40b5ea5f6 | H62: mbp-ecs-node | I62: AmazonLinux2 | J62: ami-0dfe80c71e294b99a | K62: - | L62: 10.203.3.21 | M62: running | N62: DEV / ECS Node / MBP | O62: DEVOPS | P62: 백지훈 | Q62: 서동진
... B73: 65 | C73: moinaws_dev(458493682543) | D73: ECS Node | E73: EC2 | F73: MBP | G73: i-00f5ade34561bc4d6 | H73: mbp-ecs-node | I73: AmazonLinux2 | J73: ami-0dfe80c71e294b99a | K73: - | L73: - | M73: terminated | N73: DEV / ECS Node / MBP | O73: DEVOPS | P73: 백지훈 | Q73: 서동진
B74: 66 | C74: moinaws_dev(458493682543) | D74: ECS Cluster | E74: EC2 | F74: MBP | H74: mbp | I74: - | J74: - | K74: - | L74: - | M74: O | N74: DEV / ECS Cluster / MBP | O74: DEVOPS | P74: 백지훈 | Q74: 서동진
B75: 67 | C75: moinaws_dev(458493682543) | D75: ECS Cluster | E75: EC2 | F75: 공통 | H75: core | I75: - | J75: - | K75: - | L75: - | M75: O | N75: DEV / ECS Cluster / Core | O75: DEVOPS | P75: 백지훈 | Q75: 서동진
B76: 68 | C76: moin(579643498642) | D76: ECS Node | E76: EC2 | F76: MA | G76: i-016ed7c85b36abef5 | H76: ECS Instance - EC2ContainerService-devapi | I76: AmazonLinux2 | J76: ami-0dfe80c71e294b99a | K76: 43.203.249.233 | L76: 172.25.2.228 | M76: running | N76: ECS / Worker / devapi | O76: DEVOPS | P76: 백지훈 | Q76: 서동진
...

Sheet 2. 네트워크
B2: 네트워크 목록
B4: 자산분류 | D4: ='자산분류기준'!C9 -> 네트워크
B5: 설명 | D5: ='자산분류기준'!D9 -> 서비스 운영 및 제반 업무를 위해 설치된 네트워크 장비
B7: No | D7: 자산정보 | L7: 관리자 정보 | O7: 자산중요도 평가항목 | T7: 비고
C8: 위치 | D8: 유형 | E8: 구분 | F8: 서비스구분 | G8: ID | H8: 호스트네임 | I8: IP(Domain) | J8: 사용유무 | K8: 용도 | L8: 관리부서 | M8: 책임자 | N8: 운영자 | O8: 기밀성(C) | P8: 무결성(I) | Q8: 가용성(A) | R8: 합계 | S8: 자산등급
B9: 1 | C9: moinaws(016954873025) | D9: L3 | E9: AWS TransitGW | F9: 공통 | G9: tgw-0d8b733afa9680a56 | H9: moin-prd-tgw | I9: https://016954873025-ztxsi4en.ap-northeast-2.console.aws.amazon.com/vpcconsole/home?region=ap-northeast-2#TransitGatewayDetails:transitGatewayId=tgw-0d8b733afa9680a56 | J9: O | K9: AWS VPC Transitgateway | L9: DEVOPS | M9: 백지훈 | N9: 서동진 | R9: =SUM(O9:Q9) -> 0 | S9: =IF(R9>7,"1등급",(IF(R9>4,"2등급",(IF(R9>2,"3등급","")))))
B10: 2 | C10: moin(579643498642) | D10: NatGateway | E10: AWS NatGateway | F10: MA | G10: nat-06f7883f1fe99e79b | H10: ma-ovpn-ap-northeast-2a | I10: 3.36.21.62 | J10: O | K10: VPN egress | L10: DEVOPS | M10: 백지훈 | N10: 서동진 | R10: =SUM(O10:Q10) -> 0 | S10: =IF(R10>7,"1등급",(IF(R10>4,"2등급",(IF(R10>2,"3등급",""))))) | T10: vpc-0ec48e002a7632f39 / ma-ovpn
B11: 3 | C11: moin(579643498642) | D11: NatGateway | E11: AWS NatGateway | F11: MA | G11: nat-0cb2fc740adcd4b2d | H11: ma-wordpress | I11: 3.39.130.14 | J11: O | K11: 블로그 egress | L11: DEVOPS | M11: 백지훈 | N11: 서동진 | R11: =SUM(O11:Q11) -> 0 | S11: =IF(R11>7,"1등급",(IF(R11>4,"2등급",(IF(R11>2,"3등급",""))))) | T11: vpc-00e72c942c01eed73 / ma-wordpress-vpc
B12: 4 | C12: moinaws(016954873025) | D12: NatGateway | E12: AWS NatGateway | F12: 공통 | G12: nat-07d4089b3a1901543 | H12: moin-prd-egress-nat | I12: 3.36.224.53 | J12: O | K12: 운영망 egress | L12: DEVOPS | M12: 백지훈 | N12: 서동진 | R12: =SUM(O12:Q12) -> 0 | S12: =IF(R12>7,"1등급",(IF(R12>4,"2등급",(IF(R12>2,"3등급",""))))) | T12: vpc-08d80d25067e057e5 / moin-prd-security-vpc
B13: 5 | C13: moinaws(016954873025) | D13: DNS | E13: route53 resolver | F13: 공통 | G13: rslvr-in-fe9da5066ba945369 | H13: moin-workspace | I13: 10.24.0.214, 10.24.1.66 | J13: O | K13: 내부망 DNS | L13: DEVOPS | M13: 백지훈 | N13: 서동진 | R13: =SUM(O13:Q13) -> 0 | S13: =IF(R13>7,"1등급",(IF(R13>4,"2등급",(IF(R13>2,"3등급","")))))
B14: 6 | C14: moin(579643498642) | D14: Anycast Routing | E14: AWS Global Accelerator | F14: (TERMINATED) | G14: - | H14: moin-prod-api | I14: 15.197.150.212, 3.33.147.253 | J14: X | K14: N/A | L14: DEVOPS | M14: 백지훈 | N14: 서동진 | R14: =SUM(O14:Q14) -> 0 | S14: =IF(R14>7,"1등급",(IF(R14>4,"2등급",(IF(R14>2,"3등급","")))))
B15: 7 | C15: moin(579643498642) | D15: Anycast Routing | E15: AWS Global Accelerator | F15: (TERMINATED) | G15: - | H15: mbpapi-accelerator | I15: 15.197.154.216, 3.33.146.212 | J15: X | K15: N/A | L15: DEVOPS | M15: 백지훈 | N15: 서동진 | R15: =SUM(O15:Q15) -> 0 | S15: =IF(R15>7,"1등급",(IF(R15>4,"2등급",(IF(R15>2,"3등급","")))))
B16: 8 | C16: moinaws(016954873025) | D16: CDN | E16: Cloudfront | F16: (TERMINATED) | G16: - | H16: E37S6Z2EOUB59K | I16: d358cy7yeigil6.cloudfront.net | J16: X | K16: N/A | L16: DEVOPS | M16: 백지훈 | N16: 서동진
B17: 9 | C17: moinaws(016954873025) | D17: CDN | E17: Cloudfront | F17: (TERMINATED) | G17: - | H17: E1LDARG718XHWP | I17: d3tnk8fkp9ixs3.cloudfront.net | J17: X | K17: N/A | L17: DEVOPS | M17: 백지훈 | N17: 서동진
B18: 10 | C18: moin(579643498642) | D18: CDN | E18: Cloudfront | F18: MA | G18: - | H18: E32LMS5QGU94BL | I18: d6bm2pulqv4mn.cloudfront.net | J18: O | K18: 모인 웹 프론트 개발 페이지 | L18: DEVOPS | M18: 백지훈 | N18: 서동진
B19: 11 | C19: moin(579643498642) | D19: CDN | E19: Cloudfront | F19: MA | G19: - | H19: E873LGK8O3G6B | I19: d27xkz6s3vg3pn.cloudfront.net | J19: O | K19: 모인 웹 프론트 운영 페이지 | L19: DEVOPS | M19: 백지훈 | N19: 서동진
B20: 12 | C20: moin(579643498642) | D20: CDN | E20: Cloudfront | F20: (TERMINATED) | G20: - | H20: E28PS1YUD62Y6B | I20: d1t5yk6bzfe2i.cloudfront.net | J20: X | K20: N/A | L20: DEVOPS | M20: 백지훈 | N20: 서동진
B21: 13 | C21: moin(579643498642) | D21: CDN | E21: Cloudfront | F21: 공통 | G21: - | H21: E12WJULQI8RJDA | I21: d2kd7xy8wsum7v.cloudfront.net | J21: O | K21: 공통 이미지 에셋 | L21: DEVOPS | M21: 백지훈 | N21: 서동진
B22: 14 | C22: moin(579643498642) | D22: CDN | E22: Cloudfront | F22: (TERMINATED) | G22: - | H22: E36U4G5XSXGATT | I22: d2idyqbiapxdoz.cloudfront.net | J22: X | K22: N/A | L22: DEVOPS | M22: 백지훈 | N22: 서동진
B23: 15 | C23: moin(579643498642) | D23: CDN | E23: Cloudfront | F23: (TERMINATED) | G23: - | H23: E1J159BJ2E5I4Z | I23: d2y89mat11xy0p.cloudfront.net | J23: X | K23: N/A | L23: DEVOPS | M23: 백지훈 | N23: 서동진
B24: 16 | C24: moin(579643498642) | D24: CDN | E24: Cloudfront | F24: (TERMINATED) | G24: - | H24: E3BSHFHU97ALZU | I24: d2zejs530jj2gz.cloudfront.net | J24: X | K24: N/A | L24: DEVOPS | M24: 백지훈 | N24: 서동진
B25: 17 | C25: moin(579643498642) | D25: CDN | E25: Cloudfront | F25: (TERMINATED) | G25: - | H25: EE1XY2HDPOUMF | I25: d1tt2ls41p8iod.cloudfront.net | J25: X | K25: N/A | L25: DEVOPS | M25: 백지훈 | N25: 서동진
B26: 18 | C26: moin(579643498642) | D26: CDN | E26: Cloudfront | F26: (TERMINATED) | G26: - | H26: E1T605AVO28HIS | I26: d1pfujhsuxqcke.cloudfront.net | J26: X | K26: N/A | L26: DEVOPS | M26: 백지훈 | N26: 서동진
B27: 19 | C27: moin(579643498642) | D27: CDN | E27: Cloudfront | F27: (TERMINATED) | G27: - | H27: E2W5SYZ2JXSYU3 | I27: d2wg3lae6er80f.cloudfront.net | J27: X | K27: N/A | L27: DEVOPS | M27: 백지훈 | N27: 서동진
... B33: 25 | C33: moinaws_dev(458493682543) | D33: CDN | E33: Cloudfront | F33: MBP | G33: - | H33: E215R8MDPYG8HO | I33: d217u0cdymryxe.cloudfront.net | J33: O | K33: 개발 MBP 어드민 정적 리소스 | L33: DEVOPS | M33: 백지훈 | N33: 서동진
B34: 26 | C34: moinaws_staging(920445575136) | D34: CDN | E34: Cloudfront | F34: (TERMINATED) | G34: - | H34: E1UEO1SPIDAG9Y | I34: dkfjis00z51e8.cloudfront.net | J34: X | K34: N/A | L34: DEVOPS | M34: 백지훈 | N34: 서동진 | T34: 원본 도메인: moin-stg-mbp-client-web.s3.ap-northeast-2.amazonaws.com
B35: 27 | C35: moinaws_staging(920445575136) | D35: CDN | E35: Cloudfront | F35: (TERMINATED) | G35: - | H35: E3KOE7MBH9DSI2 | I35: d3m8icbc5797cn.cloudfront.net | J35: X | K35: N/A | L35: DEVOPS | M35: 백지훈 | N35: 서동진 | T35: 원본 도메인: moin-stg-mbp-client-admin.s3.ap-northeast-2.amazonaws.com
B36: 28 | C36: 선정릉 오피스 4층 | D36: AP Controller | E36: T5004 | F36: (TERMINATED) | G36: - | H36: T5004 | I36: 192.168.0.2 | J36: X | K36: AP Controller | L36: 정보보안팀 | M36: 이윤혁 | N36: 주상욱
B37: 29 | C37: 선정릉 오피스 5층 | D37: AP | E37: IPTime Ring AX | F37: (TERMINATED) | G37: - | H37: Ring AX - A | I37: 192.168.0.38 | J37: X | K37: AP Agent 5층 | L37: 정보보안팀 | M37: 이윤혁 | N37: 주상욱
B38: 30 | C38: 선정릉 오피스 5층 | D38: AP | E38: IPTime Ring AX | F38: (TERMINATED) | G38: - | H38: Ring AX - B | I38: 192.168.0.40 | J38: X | K38: AP Agent 5층 | L38: 정보보안팀 | M38: 이윤혁 | N38: 주상욱
B39: 31 | C39: 선정릉 오피스 4층 | D39: AP | E39: IPTime Ring AX | F39: (TERMINATED) | G39: - | H39: Ring AX 4F back | I39: 192.168.0.46 | J39: X | K39: AP Agent 4층 | L39: 정보보안팀 | M39: 이윤혁 | N39: 주상욱
B40: 32 | C40: 선정릉 오피스 4층 | D40: AP | E40: IPTime Ring AX | F40: (TERMINATED) | G40: - | H40: Ring AX 4F front | I40: 192.168.0.45 | J40: X | K40: AP Agent 4층 | L40: 정보보안팀 | M40: 이윤혁 | N40: 주상욱
B41: 33 | C41: moinaws(016954873025) | D41: VPC | E41: - | F41: 공통 | G41: vpc-0fb61d357dc7aef5e | H41: workspace-vpc | I41: 10.24.0.0/16 | J41: O | K41: VDI network | L41: DEVOPS | M41: 백지훈 | N41: 서동진
B42: 34 | C42: moinaws(016954873025) | D42: VPC | E42: - | F42: 공통 | G42: vpc-06623c882681149a4 | H42: core-vpc | I42: 10.30.0.0/16 | J42: O | K42: 메인 내부망 | L42: DEVOPS | M42: 백지훈 | N42: 서동진
B43: 35 | C43: moinaws(016954873025) | D43: VPC | E43: - | F43: MBP | G43: vpc-07b42948247a19dec | H43: mbp-vpc | I43: 10.25.0.0/16 | J43: O | K43: MBP 내부망 | L43: DEVOPS | M43: 백지훈 | N43: 서동진
B44: 36 | C44: moinaws(016954873025) | D44: VPC | E44: - | F44: 공통 | G44: vpc-08d80d25067e057e5 | H44: moin-prd-security-vpc | I44: 10.14.0.0/16 | J44: O | K44: 보안솔루션 네트워크 | L44: DEVOPS | M44: 백지훈 | N44: 서동진
B45: 37 | C45: moinaws_dev(458493682543) | D45: VPC | E45: - | F45: 공통 | G45: vpc-0603464acb85fceb1 | H45: ma-ovpn | I45: 10.100.0.0/16 | J45: O | K45: vpn용 | L45: DEVOPS | M45: 백지훈 | N45: 서동진
B46: 38 | C46: moinaws_dev(458493682543) | D46: VPC | E46: - | F46: MBP | G46: vpc-05704f081ccf71460 | H46: mbp-vpc | I46: 10.203.0.0/16 | J46: O | K46: MBP 개발망 | L46: DEVOPS | M46: 백지훈 | N46: 서동진
B47: 39 | C47: moinaws_dev(458493682543) | D47: VPC | E47: - | F47: 공통 | G47: vpc-0b87119c9ff697ad4 | H47: core-vpc | I47: 10.204.0.0/16 | J47: O | K47: 메인 개발망 | L47: DEVOPS | M47: 백지훈 | N47: 서동진
... B58: 50 | C58: moin(579643498642) | D58: VPC | E58: - | F58: (TERMINATED) | G58: vpc-06c87420b4ce91460(ap-northeast-1) | H58: For Workspace AD | I58: 172.16.0.0/16 | J58: X | K58: N/A | L58: DEVOPS | M58: 백지훈 | N58: 서동진
...

Sheet 중요도평가기준
B2: 중요도평가기준
B4: 가. 목적 자산의 중요도 평가는 자산의 가치 및 중요도에 따른 보호수준을 분류하여 자산을 효율적으로 관리하도록 하는 데에 목적이 있다.
B5: 나. 중요도 평가 기준 자산 중요도 평가는 개별 자산의 정보보호 특성 중 한가지 특성이 손상되었을 경우 발생할 수 있는 예상 피해 정도와 발생 빈도를 고려하여 평가한다.
B6: 다. 정보보호 특성
B8: 분류 | C8: 설명 | D8: 평가
B9: 기밀성(C) | C9: 극비 또는 비 등급의 정보 등 노출 또는 누설 시 해당 조직에 중대한 손실 또는 불이익을 입거나, 또는 그러한 우려가 있는 경우 | D9: 상(3)
C10: 외부에 공개되는 경우 개인이나 조직의 안전 및 프라이버시에 심각한 영향을 발생시킬 수 있는 경우
C11: 자산에 대한 접근 권한이 일부인원으로 제한적일 경우(팀장, 임원, 관리자 등)
C12: 대외비 등급의 정보 등 노출 또는 누설 시 경쟁업체가 유리하게 되는 경우 | D12: 중(2)
C13: 조직 내부에서만 공유되어야 하며, 일반에게 공개되는 경우 개인이나 조직의 안전 및 프라이버시에 상당한 영향을 발생시킬 수 있는 경우
C14: 자산소유부서/담당자 이외 관련부서 등 회사 조직 내부에 국한하여 접근 및 열람이 가능한 정보를 가지고 있는 자산
C15: 홈페이지 공개자료 등 일반 등급의 정보로 노출 시 대외이미지에 손상이 없는 경우 | D15: 하(1)
C16: 회사명 조직 외부인이 접근 및 열람이 가능한 정보를 담고 있는 자산
C17: 해당 자산(장비)에 별도 정보가 기록되어 있지 않거나, 공개되어도 무방한 경우
B18: 무결성(I) | C18: 자산(정보) 변조 시, 업무수행 또는 서비스에 막대한 장애를 유발하거나 회사에 중대한 금전적 손실을 입히는 경우 | D18: 상(3)
C19: 자산(정보) 변조의 가능성이 높고, 변조 시 데이터의 무결성을 검증하기 힘든 경우
C20: 해당 자산 정보에 대한 실시간 백업이 이루어지지 않아, 원래의 정보를 복구하기 힘든 경우
C21: 자산(정보) 변조 시, 업무수행 또는 서비스에 부분적인 장애를 유발하거나 상당한 금전적 손실을 입히는 경우 | D21: 중(2)
C22: 데이터 변조의 가능성은 있으나, 데이터 변조 시 무결성 검증이 가능한 경우
C23: 임의의 무결성 검증 방법을 통해, 일정시간 내에 정보의 무결성을 복구 가능한 경우
C24: 자산이 변조되어도 업무 수행에 미치는 영향이 미흡한 경우 | D24: 하(1)
C25: 자산에 포함된 정보의 변조 가능성이 희박하고, 정보 변조 시 무결성 검증이 용이한 경우
B26: 가용성(A) | C26: 자산(정보)의 가용성 훼손 시, 업무수행 또는 서비스에 중대한 장애를 유발하는 자산 | D26: 상(3)
C27: 해당 자산이 사용 불가능할 때, 대체(백업) 자산이 없어 장기적인 업무 중단이 발생하는 경우
C28: 장애발생시 3시간 이내에 복구되어야 하는 경우
C29: 해당자산이 사용 불가능할 때 대체 자산을 투입하기까지 일부 부서에 업무장애가 발생하는 경우 | D29: 중(2)
C30: 장애 발생 시 24시간 이내에 복구되어야 하는 경우
C31: 장비 장애로 인하여 서비스 중단은 발생하지 않으나 성능에 영향을 미치는 경우
C32: 해당자산이 사용불가능 할 때, 업무장애 발생 가능성이 낮거나 영향을 미치는 범위가 극히 적은 경우 | D32: 하(1)
C33: 장애 발생 시 수일 이내에 복구되어야 하는 경우
C34: 장비 장애 시 서비스 중단 또는 성능 저하에 직접적인 영향을 미치지 않거나 백업 장비의 경우

Sheet 3. DBMS
B2: DBMS 목록
B4: 자산분류 | D4: ='자산분류기준'!C10 -> DBMS
B5: 설명 | D5: ='자산분류기준'!D10 -> 사용자가 데이터에 접근하여 데이터를 저장 및 관리 등의 기능을 제공하는 응용 소프트웨어
B7: No | E7: 자산정보 | N7: 관리자 정보 | Q7: 자산중요도 평가항목
C8: 위치 | D8: 유형 | E8: 구분 | F8: 서비스구분 | G8: ID | H8: 호스트네임 | I8: OS | J8: Ver. | K8: IP(Domain) | L8: 사용유무 | M8: 용도 | N8: 관리부서 | O8: 책임자 | P8: 운영자 | Q8: 기밀성(C) | R8: 무결성(I) | S8: 가용성(A) | T8: 합계 | U8: 자산등급
B9: 1 | C9: moinaws(016954873025) | D9: 관계형DB | E9: AWS Aurora | F9: 공통 | G9: - | H9: core-v2023-04-04-001 | I9: Aurora PostgreSQL | J9: 15.10 | K9: core-v2023-04-04-001.cluster-cudt0jie77f8.ap-northeast-2.rds.amazonaws.com | L9: O | M9: 운영 Postgresql DB | N9: DEVOPS | O9: 백지훈 | P9: 서동진 | T9: =SUM(Q9:S9) -> 0 | U9: =IF(T9>7,"1등급",(IF(T9>4,"2등급",(IF(T9>2,"3등급","")))))
B10: 2 | C10: moinaws(016954873025) | D10: 관계형DB | E10: AWS Aurora | F10: MA / MBP | G10: - | H10: moin-mysql-v2024-08-06-002 | I10: Aurora MySQL | J10: 8.0.mysql_aurora.3.07.1 | K10: moin-mysql-v2024-08-06-002.cluster-cudt0jie77f8.ap-northeast-2.rds.amazonaws.com | L10: O | M10: 운영 Mysql DB | N10: DEVOPS | O10: 백지훈 | P10: 서동진 | T10: =SUM(Q10:S10) -> 0 | U10: =IF(T10>7,"1등급",(IF(T10>4,"2등급",(IF(T10>2,"3등급","")))))
B11: 3 | C11: moin(579643498642) | D11: 관계형DB | E11: AWS RDS | F11: MBP | G11: - | H11: devapi-policy | I11: PostgreSQL | J11: 13.16 | K11: devapi-policy.c6hydqzineib.ap-northeast-2.rds.amazonaws.com | L11: O | M11: 개발 MBP 메타데이터 DB | N11: DEVOPS | O11: 백지훈 | P11: 서동진 | T11: =SUM(Q11:S11) -> 0 | U11: =IF(T11>7,"1등급",(IF(T11>4,"2등급",(IF(T11>2,"3등급","")))))
B12: 4 | C12: moin(579643498642) | D12: 관계형DB | E12: AWS Aurora | F12: MA | G12: - | H12: ma-wordpress-v2023-09-18-001 | I12: Aurora Mysql | J12: 8.0.mysql_aurora.3.05.2 | K12: ma-wordpress-v2023-09-18-001.cluster-c6hydqzineib.ap-northeast-2.rds.amazonaws.com | L12: O | M12: MA 블로그 DB | N12: DEVOPS | O12: 백지훈 | P12: 서동진 | T12: =SUM(Q12:S12) -> 0 | U12: =IF(T12>7,"1등급",(IF(T12>4,"2등급",(IF(T12>2,"3등급","")))))
B13: 5 | C13: moin(579643498642) | D13: 관계형DB | E13: AWS RDS | F13: MBP | G13: - | H13: prod-api-policy | I13: PostgreSQL | J13: 13.2 | K13: prod-api-policy.c6hydqzineib.ap-northeast-2.rds.amazonaws.com | L13: O | M13: 운영 MBP 메타데이터 DB | N13: DEVOPS | O13: 백지훈 | P13: 서동진 | T13: =SUM(Q13:S13) -> 0 | U13: =IF(T13>7,"1등급",(IF(T13>4,"2등급",(IF(T13>2,"3등급","")))))
B14: 6 | C14: moinaws_dev(458493682543) | D14: 관계형DB | E14: AWS Aurora | F14: 공통 | G14: - | H14: core-v2023-04-24-001 | I14: Aurora PostgreSQL | J14: 15.12 | K14: core-v2023-04-24-001.cluster-cxdlepzlz1vj.ap-northeast-2.rds.amazonaws.com | L14: O | M14: 개발 Postgresql DB | N14: DEVOPS | O14: 백지훈 | P14: 서동진
B15: 7 | C15: moinaws_dev(458493682543) | D15: 관계형DB | E15: AWS Aurora | F15: MA / MBP | G15: - | H15: moin-mysql-v2024-09-09-002 | I15: Aurora MySQL | J15: 8.0.mysql_aurora.3.08.2 | K15: moin-mysql-v2024-09-09-002.cluster-cxdlepzlz1vj.ap-northeast-2.rds.amazonaws.com | L15: O | M15: 개발 Mysql DB | N15: DEVOPS | O15: 백지훈 | P15: 서동진

Sheet 4. 스토리지
B2: Storage 목록
B4: 자산분류 | D4: ='자산분류기준'!C11 -> 스토리지
B5: 설명 | D5: ='자산분류기준'!D11 -> MA, MBP 서비스를 제공하기 위한 목적으로 사용되는 스토리지 모인 중요 정보를 보관하고 있는 스토리지
B7: No | H7: 자산정보 | M7: 관리자 정보 | P7: 자산중요도 평가항목 | U7: 비고
C8: 위치 | D8: 유형 | E8: 구분 | F8: 서비스구분 | G8: ID | H8: 스토리지명 | I8: IP/URL/URI | J8: 대외 서비스 여부 | K8: 사용유무 | L8: 용도 | M8: 관리부서 | N8: 책임자 | O8: 운영자 | P8: 기밀성(C) | Q8: 무결성(I) | R8: 가용성(A) | S8: 합계 | T8: 자산등급
B9: 1 | C9: moinaws(016954873025) | D9: 스토리지 | E9: AWS EFS | F9: MBP | G9: fs-046d44a6195338d56 | H9: mbp-infra-common | I9: 10.25.127.129, 10.25.146.20 | J9: X | K9: O | L9: mbp prd infra common files | M9: DEVOPS | N9: 백지훈 | O9: 서동진
B10: 2 | C10: moinaws(016954873025) | D10: 스토리지 | E10: AWS EFS | F10: 공통 | G10: fs-0b4eedae00826aa9e | H10: core-infra-common | I10: 10.30.108.178, 10.30.142.202 | J10: X | K10: O | L10: core prd infra common files | M10: DEVOPS | N10: 백지훈 | O10: 서동진
B11: 3 | C11: moinaws(016954873025) | D11: 스토리지 | E11: AWS EFS | F11: MA | G11: fs-050bdfb34b9d3ae35 | H11: ma-images | I11: 10.30.2.203, 10.30.3.103 | J11: X | K11: O | L11: MA prd user image storage | M11: DEVOPS | N11: 백지훈 | O11: 서동진
B12: 4 | C12: moinaws(016954873025) | D12: 스토리지 | E12: AWS EFS | F12: DMZ | G12: fs-024bd4883cfc162dc | H12: dmz-infra-common | I12: 10.14.5.115, 10.14.6.160 | J12: X | K12: O | L12: VPC 설정 Import | M12: DEVOPS | N12: 백지훈 | O12: 서동진
B13: 5 | C13: moinaws(016954873025) | D13: 스토리지 | E13: AWS S3 | F13: AUDIT | G13: - | H13: aws-cloudtrail-logs-016954873025-a97b878f | I13: - | J13: X | K13: O | L13: =CONCAT(F13, " object storage") -> AUDIT object storage | M13: DEVOPS | N13: 백지훈 | O13: 서동진
B14: 6 | C14: moinaws(016954873025) | D14: 스토리지 | E14: AWS S3 | F14: AUDIT | G14: - | H14: aws-waf-logs-moin-prd | I14: - | J14: X | K14: O | L14: =CONCAT(F14, " object storage") -> AUDIT object storage | M14: DEVOPS | N14: 백지훈 | O14: 서동진
B15: 7 | C15: moinaws(016954873025) | D15: 스토리지 | E15: AWS S3 | F15: AWS | G15: - | H15: cf-templates-ydf4r7mwicwt-ap-northeast-2 | I15: - | J15: X | K15: O | L15: =CONCAT(F15, " object storage") -> AWS object storage | M15: DEVOPS | N15: 백지훈 | O15: 서동진
B16: 8 | C16: moinaws(016954873025) | D16: 스토리지 | E16: AWS S3 | F16: 공통 | G16: - | H16: core-infra-20240319021140107800000001 | I16: - | J16: X | K16: O | L16: =CONCAT(F16, " object storage") -> 공통 object storage | M16: DEVOPS | N16: 백지훈 | O16: 서동진
B17: 9 | C17: moinaws(016954873025) | D17: 스토리지 | E17: AWS S3 | F17: 공통 | G17: - | H17: core-infra-common-20241119062433408800000001 | I17: - | J17: X | K17: O | L17: =CONCAT(F17, " object storage") -> 공통 object storage | M17: DEVOPS | N17: 백지훈 | O17: 서동진
B18: 10 | C18: moinaws(016954873025) | D18: 스토리지 | E18: AWS S3 | F18: MBP | G18: - | H18: mbp-infra-common-20241119081643639600000001 | I18: - | J18: X | K18: O | L18: =CONCAT(F18, " object storage") -> MBP object storage | M18: DEVOPS | N18: 백지훈 | O18: 서동진
B19: 11 | C19: moinaws(016954873025) | D19: 스토리지 | E19: AWS S3 | F19: MISC | G19: - | H19: moin-developer-operation | I19: - | J19: X | K19: O | L19: =CONCAT(F19, " object storage") -> MISC object storage | M19: DEVOPS | N19: 백지훈 | O19: 서동진
B20: 12 | C20: moinaws(016954873025) | D20: 스토리지 | E20: AWS S3 | F20: AUDIT | G20: - | H20: moin-prd-cloudtrail-logs | I20: - | J20: X | K20: O | L20: =CONCAT(F20, " object storage") -> AUDIT object storage | M20: DEVOPS | N20: 백지훈 | O20: 서동진
B21: 13 | C21: moinaws(016954873025) | D21: 스토리지 | E21: AWS S3 | F21: AUDIT | G21: - | H21: moin-prd-core-v1-31-backup | I21: - | J21: X | K21: O | L21: =CONCAT(F21, " object storage") -> AUDIT object storage | M21: DEVOPS | N21: 백지훈 | O21: 서동진
B22: 14 | C22: moinaws(016954873025) | D22: 스토리지 | E22: AWS S3 | F22: AUDIT | G22: - | H22: moin-prd-core-v1-31-loki-admin | I22: - | J22: X | K22: O | L22: =CONCAT(F22, " object storage") -> AUDIT object storage | M22: DEVOPS | N22: 백지훈 | O22: 서동진
B23: 15 | C23: moinaws(016954873025) | D23: 스토리지 | E23: AWS S3 | F23: AUDIT | G23: - | H23: moin-prd-core-v1-31-loki-chunks | I23: - | J23: X | K23: O | L23: =CONCAT(F23, " object storage") -> AUDIT object storage | M23: DEVOPS | N23: 백지훈 | O23: 서동진
B24: 16 | C24: moinaws(016954873025) | D24: 스토리지 | E24: AWS S3 | F24: AUDIT | G24: - | H24: moin-prd-core-v1-31-loki-ruler | I24: - | J24: X | K24: O | L24: =CONCAT(F24, " object storage") -> AUDIT object storage | M24: DEVOPS | N24: 백지훈 | O24: 서동진
... B36: 28 | C36: moinaws(016954873025) | D36: 스토리지 | E36: AWS S3 | F36: GLOBAL | G36: - | H36: visa-sftp-bucket | I36: - | J36: X | K36: O | L36: =CONCAT(F36, " object storage") -> GLOBAL object storage | M36: DEVOPS | N36: 백지훈 | O36: 서동진
B37: 29 | C37: moin(579643498642) | D37: 스토리지 | E37: AWS EFS | F37: MA | G37: - | H37: ma-wordpress-infra-common | I37: 10.35.94.34, 10.35.128.17 | J37: X | K37: O | L37: MA 블로그 infra common files | M37: DEVOPS | N37: 백지훈 | O37: 서동진
B38: 30 | C38: moin(579643498642) | D38: 스토리지 | E38: AWS EFS | F38: MA | G38: - | H38: ma-wordpress | I38: 10.35.2.14, 10.35.3.164 | J38: X | K38: O | L38: MA 블로그 파일 | M38: DEVOPS | N38: 백지훈 | O38: 서동진
B39: 31 | C39: moin(579643498642) | D39: 스토리지 | E39: AWS S3 | F39: INFRA | G39: - | H39: applepie-client | I39: - | J39: X | K39: O | L39: =CONCAT(F39, " object storage") -> INFRA object storage | M39: DEVOPS | N39: 백지훈 | O39: 서동진
B40: 32 | C40: moin(579643498642) | D40: 스토리지 | E40: AWS S3 | F40: AWS | G40: - | H40: config-bucket-awsconfigmoin | I40: - | J40: X | K40: O | L40: =CONCAT(F40, " object storage") -> AWS object storage | M40: DEVOPS | N40: 백지훈 | O40: 서동진
B41: 33 | C41: moin(579643498642) | D41: 스토리지 | E41: AWS S3 | F41: MA | G41: - | H41: dev-api-config | I41: - | J41: X | K41: O | L41: =CONCAT(F41, " object storage") -> MA object storage | M41: DEVOPS | N41: 백지훈 | O41: 서동진
B42: 34 | C42: moin(579643498642) | D42: 스토리지 | E42: AWS S3 | F42: MA | G42: - | H42: dev-backoffice-config | I42: - | J42: X | K42: O | L42: =CONCAT(F42, " object storage") -> MA object storage | M42: DEVOPS | N42: 백지훈 | O42: 서동진
B43: 35 | C43: moin(579643498642) | D43: 스토리지 | E43: AWS S3 | F43: MA | G43: - | H43: dev-backup-new-aws | I43: - | J43: X | K43: O | L43: =CONCAT(F43, " object storage") -> MA object storage | M43: DEVOPS | N43: 백지훈 | O43: 서동진
B44: 36 | C44: moin(579643498642) | D44: 스토리지 | E44: AWS S3 | F44: 공통 | G44: - | H44: img.themoin.com | I44: - | J44: X | K44: O | L44: =CONCAT(F44, " object storage") -> 공통 object storage | M44: DEVOPS | N44: 백지훈 | O44: 서동진
B45: 37 | C45: moin(579643498642) | D45: 스토리지 | E45: AWS S3 | F45: 공통 | G45: - | H45: img2.themoin.com | I45: - | J45: X | K45: O | L45: =CONCAT(F45, " object storage") -> 공통 object storage | M45: DEVOPS | N45: 백지훈 | O45: 서동진
B46: 38 | C46: moin(579643498642) | D46: 스토리지 | E46: AWS S3 | F46: MBP | G46: - | H46: mbp-admin-dev | I46: - | J46: X | K46: O | L46: =CONCAT(F46, " object storage") -> MBP object storage | M46: DEVOPS | N46: 백지훈 | O46: 서동진
B47: 39 | C47: moin(579643498642) | D47: 스토리지 | E47: AWS S3 | F47: MBP | G47: - | H47: mbp-client-prd | I47: - | J47: X | K47: O | L47: =CONCAT(F47, " object storage") -> MBP object storage | M47: DEVOPS | N47: 백지훈 | O47: 서동진
B48: 40 | C48: moin(579643498642) | D48: 스토리지 | E48: AWS S3 | F48: MBP | G48: - | H48: mbp-policy | I48: - | J48: X | K48: O | L48: =CONCAT(F48, " object storage") -> MBP object storage | M48: DEVOPS | N48: 백지훈 | O48: 서동진
B49: 41 | C49: moin(579643498642) | D49: 스토리지 | E49: AWS S3 | F49: MBP | G49: - | H49: mbp-server-dev | I49: - | J49: X | K49: O | L49: =CONCAT(F49, " object storage") -> MBP object storage | M49: DEVOPS | N49: 백지훈 | O49: 서동진
B50: 42 | C50: moin(579643498642) | D50: 스토리지 | E50: AWS S3 | F50: INFRA | G50: - | H50: mixpanel-import-moin-staging | I50: - | J50: X | K50: O | L50: =CONCAT(F50, " object storage") -> INFRA object storage | M50: DEVOPS | N50: 백지훈 | O50: 서동진
... B67: 59 | C67: moin(579643498642) | D67: 스토리지 | E67: AWS S3 | F67: GLOBAL | G67: - | H67: visa-sandbox | I67: - | J67: X | K67: O | L67: =CONCAT(F67, " object storage") -> GLOBAL object storage | M67: DEVOPS | N67: 백지훈 | O67: 서동진
B68: 60 | C68: moinaws_dev(458493682543) | D68: 스토리지 | E68: AWS EFS | F68: MBP | G68: fs-05f8ac4edbb560e7c | H68: mbp-infra-common | I68: 10.203.97.56, 10.203.131.127 | J68: X | K68: O | L68: mbp dev infra common files | M68: DEVOPS | N68: 백지훈 | O68: 서동진
B69: 61 | C69: moinaws_dev(458493682543) | D69: 스토리지 | E69: AWS EFS | F69: 공통 | G69: fs-041ebb69927a35e18 | H69: core-infra-common | I69: 10.204.98.246, 10.204.188.12 | J69: X | K69: O | L69: core dev infra common files | M69: DEVOPS | N69: 백지훈 | O69: 서동진
B70: 62 | C70: moinaws_dev(458493682543) | D70: 스토리지 | E70: AWS EFS | F70: MA | G70: fs-009eec7d7516289a8 | H70: ma-images | I70: 10.204.2.116, 10.204.3.216 | J70: X | K70: O | L70: MA dev user image storage | M70: DEVOPS | N70: 백지훈 | O70: 서동진
...

Sheet 5. 정보보호시스템
B2: 정보보호시스템 목록
B4: 자산분류 | C4: ='자산분류기준'!C12 -> 정보보호시스템
B5: 설명 | C5: ='자산분류기준'!D12 -> 서비스 보안 운영을 위한 장비
B7: No | C7: 자산정보 | M7: 관리자 정보 | P7: 자산중요도 평가항목 | U7: 비고
C8: 위치 | D8: 유형 | E8: 구분 | F8: 서비스 구분 | G8: 호스트네임 | H8: OS Ver. | I8: IP | J8: Serial No. | K8: 사용유무 | L8: 용도 | M8: 관리부서 | N8: 책임자 | O8: 운영자 | P8: 기밀성(C) | Q8: 무결성(I) | R8: 가용성(A) | S8: 합계 | T8: 자산등급
B9: 1 | C9: 평촌 LGU+ IDC | D9: VPN | E9: FortiGate 80F | F9: 공통 | G9: FG-80F | H9: v7.2.9 | I9: https://110.45.215.141 | J9: FGT80FTK22069838 | K9: O | L9: 대외계 VPN | M9: 정보보안팀 | N9: 이윤혁 | O9: 주상욱 | P9: 3 | Q9: 3 | R9: 3 | S9: =SUM(P9:R9) -> 9 | T9: =IF(S9>7,"1등급",(IF(S9>4,"2등급",(IF(S9>2,"3등급",""))))) -> 1등급
B10: 2 | C10: 평촌 LGU+ IDC | D10: VPN | E10: AXGATE-80D | F10: 공통 | G10: AX-80D | H10: AXGATE Gateway V2.1 SP3 2.1.0.2-octeon | I10: https://110.45.215.142 | J10: AK6N0080D23C0070 | K10: O | L10: 대외계 VPN | M10: 정보보안팀 | N10: 이윤혁 | O10: 주상욱 | P10: 3 | Q10: 3 | R10: 3 | S10: =SUM(P10:R10) -> 9 | T10: =IF(S10>7,"1등급",(IF(S10>4,"2등급",(IF(S10>2,"3등급",""))))) -> 1등급
B11: 3 | C11: 선정릉 HQ | D11: 방화벽 | E11: FortiGate 80F | F11: 공통 | G11: HQ Firewall | H11: v7.0.15 | I11: https://vpn.themoin.com | J11: - | K11: O | L11: Firewall (UTM) | M11: 정보보안팀 | N11: 이윤혁 | O11: 주상욱 | P11: 3 | Q11: 3 | R11: 3 | S11: =SUM(P11:R11) -> 9 | T11: =IF(S11>7,"1등급",(IF(S11>4,"2등급",(IF(S11>2,"3등급",""))))) -> 1등급
B12: 4 | C12: SaaS | D12: 백신/DLP | E12: 엑소스피어 | F12: 공통 | G12: 백신+DLP | H12: - | I12: https://admin.exosp.com/ | J12: - | K12: O | L12: 백신+DLP | M12: 정보보안팀 | N12: 이윤혁 | O12: 주상욱 | P12: 3 | Q12: 3 | R12: 3 | S12: =SUM(P12:R12) -> 9 | T12: =IF(S12>7,"1등급",(IF(S12>4,"2등급",(IF(S12>2,"3등급",""))))) -> 1등급
B13: 5 | C13: moin(579643498642) | D13: 웹방화벽 | E13: AWS WAF(CloudFront) | F13: 공통 | G13: CreatedByCloudFront-7b518d62-85d9-4185-aa44-f54c962c685d | H13: - | I13: CreatedByCloudFront-7b518d62-85d9-4185-aa44-f54c962c685d | J13: arn:aws:wafv2:us-east-1:579643498642:global/webacl/CreatedByCloudFront-7b518d62-85d9-4185-aa44-f54c962c685d/77ce2b84-f9ce-42a1-8a80-592fcb9e6f40 | K13: O | L13: Cloudfront의 WAF | M13: 정보보안팀 | N13: 이윤혁 | O13: 주상욱 | P13: 3 | Q13: 3 | R13: 3 | S13: =SUM(P13:R13) -> 9 | T13: =IF(S13>7,"1등급",(IF(S13>4,"2등급",(IF(S13>2,"3등급",""))))) -> 1등급
B14: 6 | C14: moin(579643498642) | D14: 웹방화벽 | E14: AWS WAF(CloudFront) | F14: 공통 | G14: CreatedByCloudFront-f5498b99-51e8-4f19-be84-3b58b9a294a8 | H14: - | I14: CreatedByCloudFront-f5498b99-51e8-4f19-be84-3b58b9a294a8 | J14: arn:aws:wafv2:us-east-1:579643498642:global/webacl/CreatedByCloudFront-f5498b99-51e8-4f19-be84-3b58b9a294a8/0c15c5fb-a901-4862-81c1-a75bca3e2a49 | K14: O | L14: Cloudfront의 WAF | M14: 정보보안팀 | N14: 이윤혁 | O14: 주상욱 | P14: 3 | Q14: 3 | R14: 3 | S14: =SUM(P14:R14) -> 9 | T14: =IF(S14>7,"1등급",(IF(S14>4,"2등급",(IF(S14>2,"3등급",""))))) -> 1등급
B15: 7 | C15: moin(579643498642) | D15: 웹방화벽 | E15: AWS WAF(CloudFront) | F15: 공통 | G15: mbp-client-acl | H15: - | I15: mbp-client-acl | J15: arn:aws:wafv2:us-east-1:579643498642:global/webacl/mbp-client-acl/6b106fa4-7b8a-4861-a3d9-649189b51934 | K15: O | L15: Cloudfront의 WAF | M15: 정보보안팀 | N15: 이윤혁 | O15: 주상욱 | P15: 3 | Q15: 3 | R15: 3 | S15: =SUM(P15:R15) -> 9 | T15: =IF(S15>7,"1등급",(IF(S15>4,"2등급",(IF(S15>2,"3등급",""))))) -> 1등급
B16: 8 | C16: moinaws(016954873025) | D16: 웹방화벽 | E16: AWS WAF(ALB) | F16: 공통 | G16: moin-prd-waf | H16: - | I16: moin-prd-waf | J16: arn:aws:wafv2:ap-northeast-2:016954873025:regional/webacl/moin-prd-waf/4edccbb0-7343-4527-ab6d-8c5fde47cdc1 | K16: O | L16: ALB의 WAF | M16: 정보보안팀 | N16: 이윤혁 | O16: 주상욱 | P16: 3 | Q16: 3 | R16: 3 | S16: =SUM(P16:R16) -> 9 | T16: =IF(S16>7,"1등급",(IF(S16>4,"2등급",(IF(S16>2,"3등급",""))))) -> 1등급
B17: 9 | C17: moin(579643498642) | D17: 웹방화벽 | E17: AWS WAF(CloudFront) | F17: 공통 | G17: moin-prd-admin-client-waf | H17: - | I17: moin-prd-admin-client-waf | J17: arn:aws:wafv2:us-east-1:016954873025:global/webacl/moin-prd-admin-client-waf/0e3bc443-bc39-49b7-8d21-162daab09fa9 | K17: O | L17: Cloudfront의 WAF | M17: 정보보안팀 | N17: 이윤혁 | O17: 주상욱 | P17: 3 | Q17: 3 | R17: 3 | S17: =SUM(P17:R17) -> 9 | T17: =IF(S17>7,"1등급",(IF(S17>4,"2등급",(IF(S17>2,"3등급",""))))) -> 1등급
B18: 10 | C18: moinaws(016954873025) | D18: 접근통제 | E18: Querypie(core-vpc/eks) | F18: 공통 | G18: querypie.int.themoin.com | H18: QueryPie 10.2.6 | I18: https://querypie.int.themoin.com | J18: - | K18: O | L18: DB/서버/K8S 접근통제 | M18: 정보보안팀 | N18: 이윤혁 | O18: 주상욱 | P18: 3 | Q18: 3 | R18: 3 | S18: =SUM(P18:R18) -> 9 | T18: =IF(S18>7,"1등급",(IF(S18>4,"2등급",(IF(S18>2,"3등급",""))))) -> 1등급
B19: 11 | C19: moinaws(016954873025) | D19: IDS/IPS | E19: AWS EC2(DeepSecurity) | F19: 공통 | G19: moin-prd-ips | H19: Red Hat Enterprise Linux release 8.6 (Ootpa) | I19: https://10.14.3.40:4119 | J19: - | K19: O | L19: IPS | M19: 정보보안팀 | N19: 이윤혁 | O19: 주상욱 | P19: 3 | Q19: 3 | R19: 3 | S19: =SUM(P19:R19) -> 9 | T19: =IF(S19>7,"1등급",(IF(S19>4,"2등급",(IF(S19>2,"3등급",""))))) -> 1등급 | U19: 마이그레이션 진행 중(삭제 예정)
B20: 12 | C20: SaaS | D20: 네트워크엑세스 | E20: FortiEMS | F20: 공통 | G20: FortiEMS(SaaS) | H20: v7.4.4 | I20: https://forticlient.forticloud.com/ems | J20: - | K20: O | L20: 네트워크 액세스 | M20: 정보보안팀 | N20: 이윤혁 | O20: 주상욱 | P20: 3 | Q20: 3 | R20: 3 | S20: =SUM(P20:R20) -> 9 | T20: =IF(S20>7,"1등급",(IF(S20>4,"2등급",(IF(S20>2,"3등급",""))))) -> 1등급

Sheet 00.지원서비스
B2: 지원서비스 목록
B4: 자산분류 | D4: ='자산분류기준'!C13 -> 지원서비스
B5: 설명 | D5: ='자산분류기준'!D13 -> 서버, DB, 스토리지 등의 정보자산이 안정적·안전하게 운영될 수 있도록 지원하는 관리형 서비스
B7: No | D7: 자산정보 | M7: 관리자 정보 | P7: 자산중요도 평가항목 | U7: 비고
C8: 위치 | D8: 유형 | E8: 구분 | F8: 서비스구분 | G8: ID | H8: 호스트네임 | I8: IP(Domain) | J8: Ver. | K8: 사용유무 | L8: 용도 | M8: 관리부서 | N8: 책임자 | O8: 운영자 | P8: 기밀성(C) | Q8: 무결성(I) | R8: 가용성(A) | S8: 합계 | T8: 자산등급
B9: 1 | C9: moin(579643498642) | D9: 키관리 | E9: kms | F9: (TERMINATED) | G9: - | H9: lambda-slack-key | I9: - | J9: - | K9: X | L9: N/A | M9: DEVOPS | N9: 백지훈 | O9: 서동진
B10: 2 | C10: moin(579643498642) | D10: 키관리 | E10: kms | F10: AUDIT | G10: - | H10: moin-cloudtrail | I10: - | J10: - | K10: O | L10: AWS cloud trail 연동키 | M10: DEVOPS | N10: 백지훈 | O10: 서동진
B11: 3 | C11: moinaws(016954873025) | D11: 키관리 | E11: kms | F11: 공통 | G11: - | H11: ee4f7462-63a5-4882-a417-59f5e06de070(별칭 없음) | I11: - | J11: - | K11: O | L11: Core Kafka key | M11: DEVOPS | N11: 백지훈 | O11: 서동진
B12: 4 | C12: moinaws(016954873025) | D12: 키관리 | E12: kms | F12: 공통 | G12: - | H12: eks/moin-prd-core-v1-31 | I12: - | J12: - | K12: O | L12: K8S 암호화 키 | M12: DEVOPS | N12: 백지훈 | O12: 서동진
B13: 5 | C13: moinaws(016954873025) | D13: 키관리 | E13: kms | F13: 공통 | G13: - | H13: moin-prod-cloudtrail | I13: - | J13: - | K13: O | L13: AWS cloud trail 연동키 | M13: DEVOPS | N13: 백지훈 | O13: 서동진
B14: 6 | C14: moinaws(016954873025) | D14: 키관리 | E14: kms | F14: mbp | G14: - | H14: s3/mbp_fxb | I14: - | J14: - | K14: O | L14: MBP 데이터 암호화 키 | M14: DEVOPS | N14: 백지훈 | O14: 서동진
B15: 7 | C15: moin(579643498642) | D15: 시크릿관리 | E15: secret manager | F15: ma | G15: - | H15: rds/wordpress | I15: - | J15: - | K15: O | L15: 어플리케이션 시크릿 관리 | M15: DEVOPS | N15: 백지훈 | O15: 서동진
B16: 8 | C16: moin(579643498642) | D16: 시크릿관리 | E16: secret manager | F16: ma | G16: - | H16: service/ma-wordpress/wordpress | I16: - | J16: - | K16: O | L16: 어플리케이션 시크릿 관리 | M16: DEVOPS | N16: 백지훈 | O16: 서동진
B17: 9 | C17: moin(579643498642) | D17: 시크릿관리 | E17: secret manager | F17: mbp | G17: - | H17: mbp-ops/seeder | I17: - | J17: - | K17: O | L17: 어플리케이션 시크릿 관리 | M17: DEVOPS | N17: 백지훈 | O17: 서동진
B18: 10 | C18: moinaws(016954873025) | D18: 시크릿관리 | E18: secret manager | F18: 공통 | G18: - | H18: rds/querypie | I18: - | J18: - | K18: O | L18: 쿼리파이 시크릿 관리 | M18: 정보보안팀 | N18: 이윤혁 | O18: 주상욱
B19: 11 | C19: moinaws(016954873025) | D19: 시크릿관리 | E19: secret manager | F19: core | G19: - | H19: service/core/aml-api | I19: - | J19: - | K19: O | L19: 어플리케이션 시크릿 관리 | M19: DEVOPS | N19: 백지훈 | O19: 서동진
B20: 12 | C20: moinaws(016954873025) | D20: 시크릿관리 | E20: secret manager | F20: core | G20: - | H20: service/core/mbp-common | I20: - | J20: - | K20: O | L20: 어플리케이션 시크릿 관리 | M20: DEVOPS | N20: 백지훈 | O20: 서동진
B21: 13 | C21: moinaws(016954873025) | D21: 시크릿관리 | E21: secret manager | F21: 공통 | G21: - | H21: opensearch/prd-seim/admin/20250218233654222400000001 | I21: - | J21: - | K21: O | L21: SIEM 시크릿 관리(Open Search) | M21: 정보보안팀 | N21: 이윤혁 | O21: 주상욱
B22: 14 | C22: moinaws(016954873025) | D22: 시크릿관리 | E22: secret manager | G22: - | H22: ecr-pullthroughcache/docker-hub | I22: - | J22: - | K22: O | L22: 어플리케이션 시크릿 관리 | M22: DEVOPS | N22: 백지훈 | O22: 서동진
B23: 15 | C23: moinaws(016954873025) | D23: 시크릿관리 | E23: secret manager | F23: core | G23: - | H23: service/core/common | I23: - | J23: - | K23: O | L23: 어플리케이션 시크릿 관리 | M23: DEVOPS | N23: 백지훈 | O23: 서동진
B24: 16 | C24: moinaws(016954873025) | D24: 시크릿관리 | E24: secret manager | F24: core | G24: - | H24: service/core/ma-global-user-api | I24: - | J24: - | K24: O | L24: 어플리케이션 시크릿 관리 | M24: DEVOPS | N24: 백지훈 | O24: 서동진
B25: 17 | C25: moinaws(016954873025) | D25: 시크릿관리 | E25: secret manager | F25: core | G25: - | H25: service/core/ma-local-kr-api | I25: - | J25: - | K25: O | L25: 어플리케이션 시크릿 관리 | M25: DEVOPS | N25: 백지훈 | O25: 서동진
B26: 18 | C26: moinaws(016954873025) | D26: 시크릿관리 | E26: secret manager | F26: core | G26: - | H26: service/core/ma-global-auth-api | I26: - | J26: - | K26: O | L26: 어플리케이션 시크릿 관리 | M26: DEVOPS | N26: 백지훈 | O26: 서동진
B27: 19 | C27: moinaws(016954873025) | D27: 시크릿관리 | E27: secret manager | F27: core | G27: - | H27: service/core/global-gateway-common | I27: - | J27: - | K27: O | L27: 어플리케이션 시크릿 관리 | M27: DEVOPS | N27: 백지훈 | O27: 서동진
B28: 20 | C28: moinaws(016954873025) | D28: 시크릿관리 | E28: secret manager | F28: core | G28: - | H28: service/core/ma-local-kr | I28: - | J28: - | K28: O | L28: 어플리케이션 시크릿 관리 | M28: DEVOPS | N28: 백지훈 | O28: 서동진
B29: 21 | C29: moinaws(016954873025) | D29: 시크릿관리 | E29: secret manager | F29: core | G29: - | H29: service/core/core-banking-worker | I29: - | J29: - | K29: O | L29: 어플리케이션 시크릿 관리 | M29: DEVOPS | N29: 백지훈 | O29: 서동진
B30: 22 | C30: moinaws(016954873025) | D30: 시크릿관리 | E30: secret manager | F30: core | G30: - | H30: service/core/ma-mkt-admin-api | I30: - | J30: - | K30: O | L30: 어플리케이션 시크릿 관리 | M30: DEVOPS | N30: 백지훈 | O30: 서동진
B31: 23 | C31: moinaws(016954873025) | D31: 시크릿관리 | E31: secret manager | F31: core | G31: - | H31: service/core/ma-common | I31: - | J31: - | K31: O | L31: 어플리케이션 시크릿 관리 | M31: DEVOPS | N31: 백지훈 | O31: 서동진
B32: 24 | C32: moinaws(016954873025) | D32: 시크릿관리 | E32: secret manager | F32: ma | G32: - | H32: rds/ma | I32: - | J32: - | K32: O | L32: 어플리케이션 시크릿 관리 | M32: DEVOPS | N32: 백지훈 | O32: 서동진
B33: 25 | C33: moinaws(016954873025) | D33: 시크릿관리 | E33: secret manager | F33: core | G33: - | H33: service/core/banking-api | I33: - | J33: - | K33: O | L33: 어플리케이션 시크릿 관리 | M33: DEVOPS | N33: 백지훈 | O33: 서동진
B34: 26 | C34: moinaws(016954873025) | D34: 시크릿관리 | E34: secret manager | F34: core | G34: - | H34: service/core/remittance-worker | I34: - | J34: - | K34: O | L34: 어플리케이션 시크릿 관리 | M34: DEVOPS | N34: 백지훈 | O34: 서동진
... B52: 44 | C52: moin(579643498642) | D52: Lambda | E52: lambda | F52: 로그 | G52: - | H52: getSupportedCurrencyList | I52: - | J52: - | K52: O | L52: 어플리케이션 시크릿 관리 | M52: DEVOPS | N52: 백지훈 | O52: 서동진
B53: 45 | C53: moinaws(016954873025) | D53: 로그관리 | E53: cloudwatch logs | F53: 로그 | G53: - | H53: /aws/ecs/containerinsights/core/performance | I53: - | J53: - | K53: O | L53: AWS managed service log | M53: DEVOPS | N53: 백지훈 | O53: 서동진 | U53: 1일
B54: 46 | C54: moinaws(016954873025) | D54: 로그관리 | E54: cloudwatch logs | F54: 로그 | G54: - | H54: /aws/ecs/containerinsights/mbp/performance | I54: - | J54: - | K54: O | L54: AWS managed service log | M54: DEVOPS | N54: 백지훈 | O54: 서동진 | U54: 1일
B55: 47 | C55: moinaws(016954873025) | D55: 로그관리 | E55: cloudwatch logs | F55: 로그 | G55: - | H55: /aws/ecs/core/aml-api | I55: - | J55: - | K55: O | L55: AWS managed service log | M55: DEVOPS | N55: 백지훈 | O55: 서동진 | U55: 무제한
B56: 48 | C56: moinaws(016954873025) | D56: 로그관리 | E56: cloudwatch logs | F56: 로그 | G56: - | H56: /aws/ecs/core/banking-api | I56: - | J56: - | K56: O | L56: AWS managed service log | M56: DEVOPS | N56: 백지훈 | O56: 서동진 | U56: 무제한
B57: 49 | C57: moinaws(016954873025) | D57: 로그관리 | E57: cloudwatch logs | F57: 로그 | G57: - | H57: /aws/ecs/core/core-banking-worker | I57: - | J57: - | K57: O | L57: AWS managed service log | M57: DEVOPS | N57: 백지훈 | O57: 서동진 | U57: 무제한
B58: 50 | C58: moinaws(016954873025) | D58: 로그관리 | E58: cloudwatch logs | F58: 로그 | G58: - | H58: /aws/ecs/core/ma-admin-frontend | I58: - | J58: - | K58: O | L58: AWS managed service log | M58: DEVOPS | N58: 백지훈 | O58: 서동진 | U58: 무제한
B59: 51 | C59: moinaws(016954873025) | D59: 로그관리 | E59: cloudwatch logs | F59: 로그 | G59: - | H59: /aws/ecs/core/ma-admin-frontend-temp | I59: - | J59: - | K59: O | L59: AWS managed service log | M59: DEVOPS | N59: 백지훈 | O59: 서동진 | U59: 무제한
B60: 52 | C60: moinaws(016954873025) | D60: 로그관리 | E60: cloudwatch logs | F60: 로그 | G60: - | H60: /aws/ecs/core/ma-admin-images | I60: - | J60: - | K60: O | L60: AWS managed service log | M60: DEVOPS | N60: 백지훈 | O60: 서동진 | U60: 무제한
...

Sheet 6. URL(추후식별)
B2: ---- 목록
B4: 자산분류 | D4: ='자산분류기준'!C14 -> URL
B5: 설명 | D5: ='자산분류기준'!D14 -> 회사, 제품, 판매 등 정보 및 서비스를 제공하기 위하여 인터넷상 구축·운영되는 서비스
B7: No | D7: 자산정보 | L7: 관리자 정보 | O7: 자산중요도 평가항목 | T7: 비고
C8: 위치 | D8: 유형 | E8: 구분 | F8: 서비스구분 | G8: URL | H8: 대외서비스 유무 | I8: 앱유무 | J8: 사용유무 | K8: 용도 | L8: 관리부서 | M8: 책임자 | N8: 운영자 | O8: 기밀성(C) | P8: 무결성(I) | Q8: 가용성(A) | R8: 합계 | S8: 자산등급
B9: 1 | D9: URL | E9: URL | F9: MA/MBP/CORE/공통 | G9: www.moinbizplus.com | H9: O | I9: O | K9: 모인비즈플러스 B2B 서비스 | O9: 3 | P9: 3 | Q9: 3 | R9: =SUM(O9:Q9) -> 9 | S9: =IF(R9>7,"1등급",(IF(R9>4,"2등급",(IF(R9>2,"3등급",""))))) -> 1등급
B10: 2 | D10: URL | E10: URL | G10: www.themoin.com | H10: O | I10: O | K10: 모인 B2C 서비스 | O10: 3 | P10: 3 | Q10: 3 | R10: =SUM(O10:Q10) -> 9 | S10: =IF(R10>7,"1등급",(IF(R10>4,"2등급",(IF(R10>2,"3등급",""))))) -> 1등급
B11: 3 | D11: URL | E11: API URL | G11: admin-api.themoin.com | R11: =SUM(O11:Q11) -> 0 | S11: =IF(R11>7,"1등급",(IF(R11>4,"2등급",(IF(R11>2,"3등급","")))))
B12: 4 | D12: URL | G12: api-prd-mbp.themoin.com | R12: =SUM(O12:Q12) -> 0 | S12: =IF(R12>7,"1등급",(IF(R12>4,"2등급",(IF(R12>2,"3등급","")))))
B13: 5 | D13: URL | G13: api-test.themoin.com | R13: =SUM(O13:Q13) -> 0 | S13: =IF(R13>7,"1등급",(IF(R13>4,"2등급",(IF(R13>2,"3등급","")))))
B14: 6 | D14: URL | G14: api.themoin.com | R14: =SUM(O14:Q14) -> 0 | S14: =IF(R14>7,"1등급",(IF(R14>4,"2등급",(IF(R14>2,"3등급","")))))
B15: 7 | D15: URL | G15: api2.themoin.com | R15: =SUM(O15:Q15) -> 0 | S15: =IF(R15>7,"1등급",(IF(R15>4,"2등급",(IF(R15>2,"3등급","")))))
B16: 8 | D16: URL | G16: apidocs.themoin.com | R16: =SUM(O16:Q16) -> 0 | S16: =IF(R16>7,"1등급",(IF(R16>4,"2등급",(IF(R16>2,"3등급","")))))
B17: 9 | D17: URL | G17: auth.themoin.com | R17: =SUM(O17:Q17) -> 0 | S17: =IF(R17>7,"1등급",(IF(R17>4,"2등급",(IF(R17>2,"3등급","")))))
B18: 10 | D18: URL | G18: cbk.themoin.com | R18: =SUM(O18:Q18) -> 0 | S18: =IF(R18>7,"1등급",(IF(R18>4,"2등급",(IF(R18>2,"3등급","")))))
B19: 11 | D19: URL | G19: cbkdev.themoin.com | R19: =SUM(O19:Q19) -> 0 | S19: =IF(R19>7,"1등급",(IF(R19>4,"2등급",(IF(R19>2,"3등급","")))))
B20: 12 | D20: URL | G20: coinmoin.themoin.com | R20: =SUM(O20:Q20) -> 0 | S20: =IF(R20>7,"1등급",(IF(R20>4,"2등급",(IF(R20>2,"3등급","")))))
B21: 13 | D21: URL | E21: URL | G21: dashboard.themoin.com | K21: 외부망 어드민 | R21: =SUM(O21:Q21) -> 0 | S21: =IF(R21>7,"1등급",(IF(R21>4,"2등급",(IF(R21>2,"3등급","")))))
B22: 14 | D22: URL | G22: devadmin.themoin.com | R22: =SUM(O22:Q22) -> 0 | S22: =IF(R22>7,"1등급",(IF(R22>4,"2등급",(IF(R22>2,"3등급","")))))
B23: 15 | D23: URL | G23: devadminapi.themoin.com | R23: =SUM(O23:Q23) -> 0 | S23: =IF(R23>7,"1등급",(IF(R23>4,"2등급",(IF(R23>2,"3등급","")))))
B24: 16 | D24: URL | G24: devadminfront.themoin.com | R24: =SUM(O24:Q24) -> 0 | S24: =IF(R24>7,"1등급",(IF(R24>4,"2등급",(IF(R24>2,"3등급","")))))
B25: 17 | D25: URL | G25: devadminimg.themoin.com | R25: =SUM(O25:Q25) -> 0 | S25: =IF(R25>7,"1등급",(IF(R25>4,"2등급",(IF(R25>2,"3등급","")))))
B26: 18 | D26: URL | G26: devapi-maadmin.themoin.com | R26: =SUM(O26:Q26) -> 0 | S26: =IF(R26>7,"1등급",(IF(R26>4,"2등급",(IF(R26>2,"3등급","")))))
B27: 19 | D27: URL | G27: devapi-maweb.themoin.com | R27: =SUM(O27:Q27) -> 0 | S27: =IF(R27>7,"1등급",(IF(R27>4,"2등급",(IF(R27>2,"3등급","")))))
B28: 20 | D28: URL | G28: devapi.themoin.com | R28: =SUM(O28:Q28) -> 0 | S28: =IF(R28>7,"1등급",(IF(R28>4,"2등급",(IF(R28>2,"3등급","")))))
B29: 21 | D29: URL | G29: devapi4.themoin.com | R29: =SUM(O29:Q29) -> 0 | S29: =IF(R29>7,"1등급",(IF(R29>4,"2등급",(IF(R29>2,"3등급","")))))
B30: 22 | D30: URL | G30: api.develop.themoin.com | R30: =SUM(O30:Q30) -> 0 | S30: =IF(R30>7,"1등급",(IF(R30>4,"2등급",(IF(R30>2,"3등급","")))))
B31: 23 | D31: URL | G31: client.develop.themoin.com | R31: =SUM(O31:Q31) -> 0 | S31: =IF(R31>7,"1등급",(IF(R31>4,"2등급",(IF(R31>2,"3등급","")))))
B32: 24 | D32: URL | G32: rancher.develop.themoin.com | R32: =SUM(O32:Q32) -> 0 | S32: =IF(R32>7,"1등급",(IF(R32>4,"2등급",(IF(R32>2,"3등급","")))))
B33: 25 | D33: URL | G33: devmktadminapi.themoin.com | R33: =SUM(O33:Q33) -> 0 | S33: =IF(R33>7,"1등급",(IF(R33>4,"2등급",(IF(R33>2,"3등급","")))))
... B90: 82 | D90: URL | G90: admin.moinbizplus.com | R90: =SUM(O90:Q90) -> 0 | S90: =IF(R90>7,"1등급",(IF(R90>4,"2등급",(IF(R90>2,"3등급","")))))
B91: 83 | D91: URL | E91: URL | F91: MBP | G91: dev.moinbizplus.com | H91: X | K91: Dev Web | R91: =SUM(O91:Q91) -> 0 | S91: =IF(R91>7,"1등급",(IF(R91>4,"2등급",(IF(R91>2,"3등급","")))))
B92: 84 | D92: URL | E92: URL | F92: MBP | G92: devadmin.moinbizplus.com | H92: X | K92: Dev Admin | R92: =SUM(O92:Q92) -> 0 | S92: =IF(R92>7,"1등급",(IF(R92>4,"2등급",(IF(R92>2,"3등급","")))))
B93: 85 | D93: URL | G93: edu.moinbizplus.com | R93: =SUM(O93:Q93) -> 0 | S93: =IF(R93>7,"1등급",(IF(R93>4,"2등급",(IF(R93>2,"3등급","")))))
B94: 86 | D94: URL | G94: www.edu.moinbizplus.com | R94: =SUM(O94:Q94) -> 0 | S94: =IF(R94>7,"1등급",(IF(R94>4,"2등급",(IF(R94>2,"3등급","")))))
B95: 87 | D95: URL | G95: eng.moinbizplus.com | R95: =SUM(O95:Q95) -> 0 | S95: =IF(R95>7,"1등급",(IF(R95>4,"2등급",(IF(R95>2,"3등급","")))))
B96: 88 | D96: URL | G96: www.eng.moinbizplus.com | R96: =SUM(O96:Q96) -> 0 | S96: =IF(R96>7,"1등급",(IF(R96>4,"2등급",(IF(R96>2,"3등급","")))))
B97: 89 | D97: URL | G97: mbp-ssr-prod-test.moinbizplus.com | R97: =SUM(O97:Q97) -> 0 | S97: =IF(R97>7,"1등급",(IF(R97>4,"2등급",(IF(R97>2,"3등급","")))))
B98: 90 | D98: URL | G98: mbp-ssr-prod.moinbizplus.com | R98: =SUM(O98:Q98) -> 0 | S98: =IF(R98>7,"1등급",(IF(R98>4,"2등급",(IF(R98>2,"3등급","")))))
B99: 91 | D99: URL | G99: mbp-ssr.moinbizplus.com | R99: =SUM(O99:Q99) -> 0 | S99: =IF(R99>7,"1등급",(IF(R99>4,"2등급",(IF(R99>2,"3등급","")))))
...

Sheet 7. 단말기
B2: PC 목록
B4: 자산분류 | C4: ='자산분류기준'!C15 -> PC (업무망,운영망)
B5: 설명 | C5: ='자산분류기준'!D15 -> 모인 서비스 업무 및 운영에 접속하기 위한 단말기
B7: No | C7: 자산정보 | H7: 관리자 정보 | K7: 자산중요도 평가항목
C8: 구분 | D8: 자산코드 | E8: 사용자 | F8: 부서 | G8: 운영체제 | H8: 운영자 | I8: 책임자 | J8: 관리부서 | K8: 기밀성(C) | L8: 무결성(I) | M8: 가용성(A) | N8: 합계 | O8: 자산등급
B9: ex) | C9: 업무용 PC | D9: - | E9: 홍길동 | K9: 3 | L9: 3 | M9: 3 | N9: =SUM(K9:M9) -> 9 | O9: =IF(N9>7,"1등급",(IF(N9>4,"2등급",(IF(N9>2,"3등급",""))))) -> 1등급
B10: 1 | C10: 인터넷망 노트북 | D10: NT-01 | E10: 조은주 | F10: Operation Division | G10: Windows11 | H10: 조은주 | I10: 박수영 | J10: COO | N10: =SUM(K10:M10) -> 0 | O10: =IF(N10>7,"1등급",(IF(N10>4,"2등급",(IF(N10>2,"3등급","")))))
B11: 2 | C11: 인터넷망 노트북 | D11: NT-02 | E11: 신경수 | F11: Corporate Management Division | G11: Windows11 | H11: 신경수 | I11: 서일석 | J11: CEO | N11: =SUM(K11:M11) -> 0 | O11: =IF(N11>7,"1등급",(IF(N11>4,"2등급",(IF(N11>2,"3등급","")))))
B12: 3 | C12: 인터넷망 노트북 | D12: NT-04 | E12: 박수영 | F12: Product Division | G12: Windows11 | H12: 박수영 | I12: 서홍석 | J12: CPO | N12: =SUM(K12:M12) -> 0 | O12: =IF(N12>7,"1등급",(IF(N12>4,"2등급",(IF(N12>2,"3등급","")))))
B13: 4 | C13: 인터넷망 노트북 | D13: NT-07 | E13: 박창근 | F13: Product Division | G13: Windows11 | H13: 박창근 | I13: 서홍석 | J13: CPO | N13: =SUM(K13:M13) -> 0 | O13: =IF(N13>7,"1등급",(IF(N13>4,"2등급",(IF(N13>2,"3등급","")))))
B14: 5 | C14: 인터넷망 노트북 | D14: NT-100 | E14: 염동욱 | F14: Product Division | G14: MacOS | H14: 염동욱 | I14: 서홍석 | J14: CPO | N14: =SUM(K14:M14) -> 0 | O14: =IF(N14>7,"1등급",(IF(N14>4,"2등급",(IF(N14>2,"3등급","")))))
B15: 6 | C15: 인터넷망 노트북 | D15: NT-101 | E15: 한채연 | F15: Product Division | G15: MacOS | H15: 한채연 | I15: 서홍석 | J15: CPO | N15: =SUM(K15:M15) -> 0 | O15: =IF(N15>7,"1등급",(IF(N15>4,"2등급",(IF(N15>2,"3등급","")))))
B16: 7 | C16: 인터넷망 노트북 | D16: NT-102 | E16: 박나은 | F16: Operation Division | G16: Windows11 | H16: 박나은 | I16: 박수영 | J16: COO | N16: =SUM(K16:M16) -> 0 | O16: =IF(N16>7,"1등급",(IF(N16>4,"2등급",(IF(N16>2,"3등급","")))))
B17: 8 | C17: 인터넷망 노트북 | D17: NT-103 | E17: 김형준 | F17: Product Division | G17: MacOS | H17: 김형준 | I17: 서홍석 | J17: CPO | N17: =SUM(K17:M17) -> 0 | O17: =IF(N17>7,"1등급",(IF(N17>4,"2등급",(IF(N17>2,"3등급","")))))
B18: 9 | C18: 인터넷망 노트북 | D18: NT-104 | E18: 조민정 | F18: Product Division | G18: MacOS | H18: 조민정 | I18: 서홍석 | J18: CPO
B19: 10 | C19: 인터넷망 노트북 | D19: NT-105 | E19: 김성호 | F19: Product Division | G19: MacOS | H19: 김성호 | I19: 서홍석 | J19: CPO
B20: 11 | C20: 인터넷망 노트북 | D20: NT-15 | E20: 서일석 | F20: CEO | G20: Windows11 | H20: 서일석 | I20: 서일석 | J20: CEO | N20: =SUM(K20:M20) -> 0 | O20: =IF(N20>7,"1등급",(IF(N20>4,"2등급",(IF(N20>2,"3등급","")))))
B21: 12 | C21: 인터넷망 노트북 | D21: NT-17 | E21: 차승용 | F21: Product Division | G21: MacOS | H21: 차승용 | I21: 서홍석 | J21: CPO | N21: =SUM(K21:M21) -> 0 | O21: =IF(N21>7,"1등급",(IF(N21>4,"2등급",(IF(N21>2,"3등급","")))))
B22: 13 | C22: 인터넷망 노트북 | D22: NT-18 | E22: 조예지 | F22: Growth Division | G22: MacOS | H22: 조예지 | I22: 김태우 | J22: Growth Division | N22: =SUM(K22:M22) -> 0 | O22: =IF(N22>7,"1등급",(IF(N22>4,"2등급",(IF(N22>2,"3등급","")))))
B23: 14 | C23: 인터넷망 노트북 | D23: NT-20 | E23: 허선아 | F23: Growth Division | G23: MacOS | H23: 허선아 | I23: 김태우 | J23: Growth Division | N23: =SUM(K23:M23) -> 0 | O23: =IF(N23>7,"1등급",(IF(N23>4,"2등급",(IF(N23>2,"3등급","")))))
B24: 15 | C24: 인터넷망 노트북 | D24: NT-22 | E24: 신민경 | F24: Growth Division | G24: Windows11 | H24: 허선아 | I24: 김태우 | J24: Growth Division
B25: 16 | C25: 인터넷망 노트북 | D25: NT-23 | E25: 고선우 | F25: Business Development Division | G25: MacOS | H25: 고선우 | I25: 허성현 | J25: CBDO
B26: 17 | C26: 인터넷망 노트북 | D26: NT-24 | E26: 김정한 | F26: Product Division | G26: MacOS | H26: 김정한 | I26: 서홍석 | J26: CPO | N26: =SUM(K26:M26) -> 0 | O26: =IF(N26>7,"1등급",(IF(N26>4,"2등급",(IF(N26>2,"3등급","")))))
B27: 18 | C27: 인터넷망 노트북 | D27: NT-25 | E27: 김대원 | F27: Operation Division | G27: Windows11 | H27: 김대원 | I27: 박수영 | J27: COO | N27: =SUM(K27:M27) -> 0 | O27: =IF(N27>7,"1등급",(IF(N27>4,"2등급",(IF(N27>2,"3등급","")))))
B28: 19 | C28: 인터넷망 노트북 | D28: NT-26 | E28: 이아람 | F28: Operation Division | G28: Windows11 | H28: 이아람 | I28: 박수영 | J28: COO | N28: =SUM(K28:M28) -> 0 | O28: =IF(N28>7,"1등급",(IF(N28>4,"2등급",(IF(N28>2,"3등급","")))))
B29: 20 | C29: 인터넷망 노트북 | D29: NT-27 | E29: 홍서영 | F29: Operation Division | G29: Windows11 | H29: 홍서영 | I29: 박수영 | J29: COO | N29: =SUM(K29:M29) -> 0 | O29: =IF(N29>7,"1등급",(IF(N29>4,"2등급",(IF(N29>2,"3등급","")))))
B30: 21 | C30: 인터넷망 노트북 | D30: NT-28 | E30: 박유빈 | F30: Operation Division | G30: Windows11 | H30: 박유빈 | I30: 박수영 | J30: COO | N30: =SUM(K30:M30) -> 0 | O30: =IF(N30>7,"1등급",(IF(N30>4,"2등급",(IF(N30>2,"3등급","")))))
B31: 22 | C31: 인터넷망 노트북 | D31: NT-30 | E31: 김초롱 | F31: Product Division | G31: MacOS | H31: 김초롱 | I31: 서홍석 | J31: CPO | N31: =SUM(K31:M31) -> 0 | O31: =IF(N31>7,"1등급",(IF(N31>4,"2등급",(IF(N31>2,"3등급","")))))
B32: 23 | C32: 인터넷망 노트북 | D32: NT-31 | E32: 임희정 | F32: Business Development Division | G32: MacOS | H32: 임희정 | I32: 허성현 | J32: CBDO | N32: =SUM(K32:M32) -> 0 | O32: =IF(N32>7,"1등급",(IF(N32>4,"2등급",(IF(N32>2,"3등급","")))))
B33: 24 | C33: 인터넷망 노트북 | D33: NT-33 | E33: 이봉구 | F33: Product Division | G33: MacOS | H33: 이봉구 | I33: 서홍석 | J33: CPO | N33: =SUM(K33:M33) -> 0 | O33: =IF(N33>7,"1등급",(IF(N33>4,"2등급",(IF(N33>2,"3등급","")))))
B34: 25 | C34: 인터넷망 노트북 | D34: NT-36 | E34: 유영진 | F34: Corporate Management Division | G34: Windows11 | H34: 유영진 | I34: 서일석 | J34: CEO | N34: =SUM(K34:M34) -> 0 | O34: =IF(N34>7,"1등급",(IF(N34>4,"2등급",(IF(N34>2,"3등급","")))))
B35: 26 | C35: 인터넷망 노트북 | D35: NT-37 | E35: 허성현 | F35: Business Development Division | G35: Windows11 | H35: 허성현 | I35: 허성현 | J35: CBDO | N35: =SUM(K35:M35) -> 0 | O35: =IF(N35>7,"1등급",(IF(N35>4,"2등급",(IF(N35>2,"3등급","")))))
B36: 27 | C36: 인터넷망 노트북 | D36: NT-38 | E36: 박수영 | F36: Operation Division | G36: Windows11 | H36: 박수영 | I36: 박수영 | J36: COO | N36: =SUM(K36:M36) -> 0 | O36: =IF(N36>7,"1등급",(IF(N36>4,"2등급",(IF(N36>2,"3등급","")))))
B37: 28 | C37: 인터넷망 노트북 | D37: NT-39 | E37: 이민호 | F37: Product Division | G37: MacOS | H37: 이민호 | I37: 서홍석 | J37: CPO | N37: =SUM(K37:M37) -> 0 | O37: =IF(N37>7,"1등급",(IF(N37>4,"2등급",(IF(N37>2,"3등급","")))))
